Workbook
Name PeriodList: Lists!$A$2:$A$5

Sheet Sheet1
A2: (단위 : 천톤, 백만$)
A3: 년월 | B3: 계획실적 | C3: 구분 | D3: 중국1 | E3: 중국2 | F3: 중국3 | G3: 중국4 | H3: 인도1 | I3: 인도2 | J3: 인도3 | K3: 유럽1 | L3: 유럽2 | M3: 유럽3 | N3: 유럽4 | O3: 미주1 | P3: 미주2 | Q3: 미주3 | R3: 미주4 | S3: 합계
A4: 46023 | B4: 계획 | C4: 판매량 | D4: 8 | E4: 8 | F4: 8 | G4: 4 | H4: 8 | I4: 8 | J4: 8 | K4: 8 | L4: 8 | M4: 8 | N4: 8 | O4: 8 | P4: 8 | Q4: 8 | R4: 8 | S4: =+SUM(D4:F4,H4:R4) -> 112
A5: 46023 | B5: 계획 | C5: 매출액 | D5: 8 | E5: 8 | F5: 8 | G5: 4 | H5: 8 | I5: 8 | J5: 8 | K5: 8 | L5: 8 | M5: 8 | N5: 8 | O5: 8 | P5: 8 | Q5: 8 | R5: 8 | S5: =+SUM(D5:F5,H5:R5) -> 112
A6: 46023 | B6: 계획 | C6: 매출원가 | D6: =+SUM(D7:D9) -> 5 | E6: =+SUM(E7:E9) -> 5 | F6: =+SUM(F7:F9) -> 5 | G6: =+SUM(G7:G9) -> 3 | H6: =+SUM(H7:H9) -> 5 | I6: =+SUM(I7:I9) -> 5 | J6: =+SUM(J7:J9) -> 5 | K6: =+SUM(K7:K9) -> 5 | ... R6: =+SUM(R7:R9) -> 5 | S6: =+S5-S10 -> 69
A7: 46023 | B7: 계획 | C7: - 재료비 | D7: 3 | E7: 3 | F7: 3 | G7: 3 | H7: 3 | I7: 3 | J7: 3 | K7: 3 | L7: 3 | M7: 3 | N7: 3 | O7: 3 | P7: 3 | Q7: 3 | R7: 3 | S7: =+S6-S8-S9 -> 41
A8: 46023 | B8: 계획 | C8: - 노무비 | D8: 1 | E8: 1 | F8: 1 | H8: 1 | I8: 1 | J8: 1 | K8: 1 | L8: 1 | M8: 1 | N8: 1 | O8: 1 | P8: 1 | Q8: 1 | R8: 1 | S8: =+SUM(D8:F8,H8:R8) -> 14
A9: 46023 | B9: 계획 | C9: - 경비 | D9: 1 | E9: 1 | F9: 1 | H9: 1 | I9: 1 | J9: 1 | K9: 1 | L9: 1 | M9: 1 | N9: 1 | O9: 1 | P9: 1 | Q9: 1 | R9: 1 | S9: =+SUM(D9:F9,H9:R9) -> 14
A10: 46023 | B10: 계획 | C10: 매출총이익 | D10: =+D5-D6 -> 3 | E10: =+E5-E6 -> 3 | F10: =+F5-F6 -> 3 | G10: =+G5-G6 -> 1 | H10: =+H5-H6 -> 3 | I10: =+I5-I6 -> 3 | J10: =+J5-J6 -> 3 | K10: =+K5-K6 -> 3 | ... R10: =+R5-R6 -> 3 | S10: =+SUM(D10:R10) -> 43
A11: 46023 | B11: 계획 | C11: 판관비 | D11: 1 | E11: 1 | F11: 1 | G11: 1 | H11: 1 | I11: 1 | J11: 1 | K11: 1 | L11: 1 | M11: 1 | N11: 1 | O11: 1 | P11: 1 | Q11: 1 | R11: 1 | S11: =+SUM(D11:R11) -> 15
A12: 46023 | B12: 계획 | C12: 영업이익 | D12: =+D10-D11 -> 2 | E12: =+E10-E11 -> 2 | F12: =+F10-F11 -> 2 | G12: =+G10-G11 -> 0 | H12: =+H10-H11 -> 2 | I12: =+I10-I11 -> 2 | J12: =+J10-J11 -> 2 | K12: =+K10-K11 -> 2 | ... S12: =+S10-S11 -> 28
A13: 46023 | B13: 계획 | C13: 영업외 | D13: -1 | E13: -1 | F13: -1 | G13: -1 | H13: -1 | I13: -1 | J13: -1 | K13: -1 | L13: -1 | M13: -1 | N13: -1 | O13: -1 | P13: -1 | Q13: -1 | R13: -1 | S13: =+S14-S12 -> -15
A14: 46023 | B14: 계획 | C14: 경상이익 | D14: =+D12+D13 -> 1 | E14: =+E12+E13 -> 1 | F14: =+F12+F13 -> 1 | G14: =+G12+G13 -> -1 | H14: =+H12+H13 -> 1 | I14: =+I12+I13 -> 1 | J14: =+J12+J13 -> 1 | K14: =+K12+K13 -> 1 | ... R14: =+R12+R13 -> 1 | S14: =+SUM(D14:R14) -> 13
A15: 46023 | B15: 실적 | C15: 판매량 | D15: 7 | E15: 7 | F15: 7 | G15: 4 | H15: 6 | I15: 6 | J15: 6 | K15: 9 | L15: 9 | N15: 9 | O15: 12 | P15: 12 | Q15: 12 | R15: 12 | S15: =+SUM(D15:F15,H15:R15) -> 114
A16: 46023 | B16: 실적 | C16: 매출액 | D16: 5 | E16: 5 | F16: 5 | G16: 4 | H16: 8 | I16: 8 | J16: 8 | K16: 8 | L16: 8 | N16: 8 | O16: 16 | P16: 16 | Q16: 16 | R16: 16 | S16: =+SUM(D16:F16,H16:R16) -> 127
A17: 46023 | B17: 실적 | C17: 매출원가 | D17: =+SUM(D18:D20) -> 4 | E17: =+SUM(E18:E20) -> 4 | F17: =+SUM(F18:F20) -> 4 | G17: =+SUM(G18:G20) -> 3 | H17: =+SUM(H18:H20) -> 6 | I17: =+SUM(I18:I20) -> 6 | J17: =+SUM(J18:J20) -> 6 | K17: =+SUM(K18:K20) -> 6 | ... R17: =+SUM(R18:R20) -> 10 | S17: =+S16-S21 -> 87
A18: 46023 | B18: 실적 | C18: - 재료비 | D18: 2 | E18: 2 | F18: 2 | G18: 3 | H18: 4 | I18: 4 | J18: 4 | K18: 4 | L18: 4 | N18: 4 | O18: 8 | P18: 8 | Q18: 8 | R18: 8 | S18: =+S17-S19-S20 -> 61
A19: 46023 | B19: 실적 | C19: - 노무비 | D19: 1 | E19: 1 | F19: 1 | H19: 1 | I19: 1 | J19: 1 | K19: 1 | L19: 1 | N19: 1 | O19: 1 | P19: 1 | Q19: 1 | R19: 1 | S19: =+SUM(D19:F19,H19:R19) -> 13
A20: 46023 | B20: 실적 | C20: - 경비 | D20: 1 | E20: 1 | F20: 1 | H20: 1 | I20: 1 | J20: 1 | K20: 1 | L20: 1 | N20: 1 | O20: 1 | P20: 1 | Q20: 1 | R20: 1 | S20: =+SUM(D20:F20,H20:R20) -> 13
A21: 46023 | B21: 실적 | C21: 매출총이익 | D21: =+D16-D17 -> 1 | E21: =+E16-E17 -> 1 | F21: =+F16-F17 -> 1 | G21: =+G16-G17 -> 1 | H21: =+H16-H17 -> 2 | I21: =+I16-I17 -> 2 | J21: =+J16-J17 -> 2 | K21: =+K16-K17 -> 2 | ... R21: =+R16-R17 -> 6 | S21: =+SUM(D21:R21) -> 40
A22: 46023 | B22: 실적 | C22: 판관비 | D22: 2 | E22: 2 | F22: 2 | G22: 2 | H22: 0 | I22: 0 | J22: 0 | K22: 1 | L22: 1 | M22: 1 | N22: 1 | O22: 3 | P22: 3 | Q22: 3 | R22: 3 | S22: =+SUM(D22:R22) -> 24
A23: 46023 | B23: 실적 | C23: 영업이익 | D23: =+D21-D22 -> -1 | E23: =+E21-E22 -> -1 | F23: =+F21-F22 -> -1 | G23: =+G21-G22 -> -1 | H23: =+H21-H22 -> 2 | I23: =+I21-I22 -> 2 | J23: =+J21-J22 -> 2 | K23: =+K21-K22 -> 1 | ... S23: =+S21-S22 -> 16
A24: 46023 | B24: 실적 | C24: 영업외 | D24: 1 | E24: 1 | F24: 1 | G24: 1 | H24: -3 | I24: -3 | J24: -3 | K24: -2 | L24: -2 | M24: 3 | N24: -2 | O24: -4 | P24: -4 | Q24: -4 | R24: -4 | S24: =+S25-S23 -> -24
A25: 46023 | B25: 실적 | C25: 경상이익 | D25: =+D23+D24 -> 0 | E25: =+E23+E24 -> 0 | F25: =+F23+F24 -> 0 | G25: =+G23+G24 -> 0 | H25: =+H23+H24 -> -1 | I25: =+I23+I24 -> -1 | J25: =+J23+J24 -> -1 | K25: =+K23+K24 -> -1 | ... R25: =+R23+R24 -> -1 | S25: =+SUM(D25:R25) -> -8
A26: 46054 | B26: 계획 | C26: 판매량 | D26: 8 | E26: 8 | F26: 8 | G26: 4 | H26: 8 | I26: 8 | J26: 8 | K26: 8 | L26: 8 | M26: 8 | N26: 8 | O26: 8 | P26: 8 | Q26: 8 | R26: 8 | S26: =+SUM(D26:F26,H26:R26) -> 112
A27: 46054 | B27: 계획 | C27: 매출액 | D27: 8 | E27: 8 | F27: 8 | G27: 4 | H27: 8 | I27: 8 | J27: 8 | K27: 8 | L27: 8 | M27: 8 | N27: 8 | O27: 8 | P27: 8 | Q27: 8 | R27: 8 | S27: =+SUM(D27:F27,H27:R27) -> 112
A28: 46054 | B28: 계획 | C28: 매출원가 | D28: =+SUM(D29:D31) -> 5 | E28: =+SUM(E29:E31) -> 5 | F28: =+SUM(F29:F31) -> 5 | G28: =+SUM(G29:G31) -> 3 | H28: =+SUM(H29:H31) -> 5 | I28: =+SUM(I29:I31) -> 5 | J28: =+SUM(J29:J31) -> 5 | K28: =+SUM(K29:K31) -> 5 | ... R28: =+SUM(R29:R31) -> 5 | S28: =+S27-S32 -> 69
A29: 46054 | B29: 계획 | C29: - 재료비 | D29: 3 | E29: 3 | F29: 3 | G29: 3 | H29: 3 | I29: 3 | J29: 3 | K29: 3 | L29: 3 | M29: 3 | N29: 3 | O29: 3 | P29: 3 | Q29: 3 | R29: 3 | S29: =+S28-S30-S31 -> 41
A30: 46054 | B30: 계획 | C30: - 노무비 | D30: 1 | E30: 1 | F30: 1 | H30: 1 | I30: 1 | J30: 1 | K30: 1 | L30: 1 | M30: 1 | N30: 1 | O30: 1 | P30: 1 | Q30: 1 | R30: 1 | S30: =+SUM(D30:F30,H30:R30) -> 14
A31: 46054 | B31: 계획 | C31: - 경비 | D31: 1 | E31: 1 | F31: 1 | H31: 1 | I31: 1 | J31: 1 | K31: 1 | L31: 1 | M31: 1 | N31: 1 | O31: 1 | P31: 1 | Q31: 1 | R31: 1 | S31: =+SUM(D31:F31,H31:R31) -> 14
A32: 46054 | B32: 계획 | C32: 매출총이익 | D32: =+D27-D28 -> 3 | E32: =+E27-E28 -> 3 | F32: =+F27-F28 -> 3 | G32: =+G27-G28 -> 1 | H32: =+H27-H28 -> 3 | I32: =+I27-I28 -> 3 | J32: =+J27-J28 -> 3 | K32: =+K27-K28 -> 3 | ... R32: =+R27-R28 -> 3 | S32: =+SUM(D32:R32) -> 43
A33: 46054 | B33: 계획 | C33: 판관비 | D33: 1 | E33: 1 | F33: 1 | G33: 1 | H33: 1 | I33: 1 | J33: 1 | K33: 1 | L33: 1 | M33: 1 | N33: 1 | O33: 1 | P33: 1 | Q33: 1 | R33: 1 | S33: =+SUM(D33:R33) -> 15
A34: 46054 | B34: 계획 | C34: 영업이익 | D34: =+D32-D33 -> 2 | E34: =+E32-E33 -> 2 | F34: =+F32-F33 -> 2 | G34: =+G32-G33 -> 0 | H34: =+H32-H33 -> 2 | I34: =+I32-I33 -> 2 | J34: =+J32-J33 -> 2 | K34: =+K32-K33 -> 2 | ... S34: =+S32-S33 -> 28
A35: 46054 | B35: 계획 | C35: 영업외 | D35: -1 | E35: -1 | F35: -1 | G35: -1 | H35: -1 | I35: -1 | J35: -1 | K35: -1 | L35: -1 | M35: -1 | N35: -1 | O35: -1 | P35: -1 | Q35: -1 | R35: -1 | S35: =+S36-S34 -> -15
A36: 46054 | B36: 계획 | C36: 경상이익 | D36: =+D34+D35 -> 1 | E36: =+E34+E35 -> 1 | F36: =+F34+F35 -> 1 | G36: =+G34+G35 -> -1 | H36: =+H34+H35 -> 1 | I36: =+I34+I35 -> 1 | J36: =+J34+J35 -> 1 | K36: =+K34+K35 -> 1 | ... R36: =+R34+R35 -> 1 | S36: =+SUM(D36:R36) -> 13
A37: 46054 | B37: 실적 | C37: 판매량 | D37: 10 | E37: 10 | F37: 10 | G37: 4 | H37: 6 | I37: 6 | J37: 6 | K37: 9 | L37: 9 | N37: 9 | O37: 12 | P37: 12 | Q37: 12 | R37: 12 | S37: =+SUM(D37:F37,H37:R37) -> 123
A38: 46054 | B38: 실적 | C38: 매출액 | D38: 9 | E38: 9 | F38: 9 | G38: 4 | H38: 10 | I38: 10 | J38: 10 | K38: 8 | L38: 8 | N38: 8 | O38: 20 | P38: 20 | Q38: 20 | R38: 20 | S38: =+SUM(D38:F38,H38:R38) -> 161
A39: 46054 | B39: 실적 | C39: 매출원가 | D39: =+SUM(D40:D42) -> 3 | E39: =+SUM(E40:E42) -> 3 | F39: =+SUM(F40:F42) -> 3 | G39: =+SUM(G40:G42) -> 3 | H39: =+SUM(H40:H42) -> 7 | I39: =+SUM(I40:I42) -> 7 | J39: =+SUM(J40:J42) -> 7 | K39: =+SUM(K40:K42) -> 6 | ... R39: =+SUM(R40:R42) -> 14 | S39: =+S38-S43 -> 103
A40: 46054 | B40: 실적 | C40: - 재료비 | D40: 1 | E40: 1 | F40: 1 | G40: 3 | H40: 5 | I40: 5 | J40: 5 | K40: 4 | L40: 4 | N40: 4 | O40: 12 | P40: 12 | Q40: 12 | R40: 12 | S40: =+S39-S41-S42 -> 77
A41: 46054 | B41: 실적 | C41: - 노무비 | D41: 1 | E41: 1 | F41: 1 | H41: 1 | I41: 1 | J41: 1 | K41: 1 | L41: 1 | N41: 1 | O41: 1 | P41: 1 | Q41: 1 | R41: 1 | S41: =+SUM(D41:F41,H41:R41) -> 13
...

Sheet Lists
A1: 기준월 옵션 (당월/누계) - 향후 월 추가 시 이 목록에 행 추가
A2: 2026-01 당월
A3: 2026-01 누계
A4: 2026-02 당월
A5: 2026-02 누계

Sheet Report_P1
A1: 해외법인 손익 리포트 - 계획/실적 요약 (Page 1) | J1: 계산용 파라미터 (건드리지 마세요)
A2: 기준월 선택: | B2: 2026-02 누계 | J2: 연도 | K2: =VALUE(LEFT($B$2,4)) -> 2026
J3: 월 | K3: =VALUE(MID($B$2,6,2)) -> 2
A4: 법인 | B4: 계획-판매량 | C4: 계획-매출액 | D4: 계획-경상이익 | E4: 실적-판매량 | F4: 실적-매출액 | G4: 실적-경상이익 | H4: 차이-경상이익 | J4: 모드 | K4: =MID($B$2,9,2) -> 누계
A5: 중국1 | B5: =SUMIFS(Sheet1!D$4:D$1000,Sheet1!$A$4:$A$1000,">="&Report_P1!$K$5,Sheet1!$A$4:$A$1000,"<="&Report_P1!$K$6,Sheet1!$B$4:$B$1000,"계획",Sheet1!$C$4:$C$1000,"판매량") -> 16 | C5: =SUMIFS(Sheet1!D$4:D$1000,Sheet1!$A$4:$A$1000,">="&Report_P1!$K$5,Sheet1!$A$4:$A$1000,"<="&Report_P1!$K$6,Sheet1!$B$4:$B$1000,"계획",Sheet1!$C$4:$C$1000,"매출액") -> 16 | D5: =SUMIFS(Sheet1!D$4:D$1000,Sheet1!$A$4:$A$1000,">="&Report_P1!$K$5,Sheet1!$A$4:$A$1000,"<="&Report_P1!$K$6,Sheet1!$B$4:$B$1000,"계획",Sheet1!$C$4:$C$1000,"경상이익") -> 2 | E5: =SUMIFS(Sheet1!D$4:D$1000,Sheet1!$A$4:$A$1000,">="&Report_P1!$K$5,Sheet1!$A$4:$A$1000,"<="&Report_P1!$K$6,Sheet1!$B$4:$B$1000,"실적",Sheet1!$C$4:$C$1000,"판매량") -> 17 | F5: =SUMIFS(Sheet1!D$4:D$1000,Sheet1!$A$4:$A$1000,">="&Report_P1!$K$5,Sheet1!$A$4:$A$1000,"<="&Report_P1!$K$6,Sheet1!$B$4:$B$1000,"실적",Sheet1!$C$4:$C$1000,"매출액") -> 14 | G5: =SUMIFS(Sheet1!D$4:D$1000,Sheet1!$A$4:$A$1000,">="&Report_P1!$K$5,Sheet1!$A$4:$A$1000,"<="&Report_P1!$K$6,Sheet1!$B$4:$B$1000,"실적",Sheet1!$C$4:$C$1000,"경상이익") -> 2 | H5: =G5-D5 -> 0 | J5: 시작일 | K5: =IF($K$4="누계",DATE($K$2,1,1),DATE($K$2,$K$3,1)) -> 46023
A6: 중국2 | B6: =SUMIFS(Sheet1!E$4:E$1000,Sheet1!$A$4:$A$1000,">="&Report_P1!$K$5,Sheet1!$A$4:$A$1000,"<="&Report_P1!$K$6,Sheet1!$B$4:$B$1000,"계획",Sheet1!$C$4:$C$1000,"판매량") -> 16 | C6: =SUMIFS(Sheet1!E$4:E$1000,Sheet1!$A$4:$A$1000,">="&Report_P1!$K$5,Sheet1!$A$4:$A$1000,"<="&Report_P1!$K$6,Sheet1!$B$4:$B$1000,"계획",Sheet1!$C$4:$C$1000,"매출액") -> 16 | D6: =SUMIFS(Sheet1!E$4:E$1000,Sheet1!$A$4:$A$1000,">="&Report_P1!$K$5,Sheet1!$A$4:$A$1000,"<="&Report_P1!$K$6,Sheet1!$B$4:$B$1000,"계획",Sheet1!$C$4:$C$1000,"경상이익") -> 2 | E6: =SUMIFS(Sheet1!E$4:E$1000,Sheet1!$A$4:$A$1000,">="&Report_P1!$K$5,Sheet1!$A$4:$A$1000,"<="&Report_P1!$K$6,Sheet1!$B$4:$B$1000,"실적",Sheet1!$C$4:$C$1000,"판매량") -> 17 | F6: =SUMIFS(Sheet1!E$4:E$1000,Sheet1!$A$4:$A$1000,">="&Report_P1!$K$5,Sheet1!$A$4:$A$1000,"<="&Report_P1!$K$6,Sheet1!$B$4:$B$1000,"실적",Sheet1!$C$4:$C$1000,"매출액") -> 14 | G6: =SUMIFS(Sheet1!E$4:E$1000,Sheet1!$A$4:$A$1000,">="&Report_P1!$K$5,Sheet1!$A$4:$A$1000,"<="&Report_P1!$K$6,Sheet1!$B$4:$B$1000,"실적",Sheet1!$C$4:$C$1000,"경상이익") -> 2 | H6: =G6-D6 -> 0 | J6: 종료일 | K6: =DATE($K$2,$K$3,1) -> 46054
A7: 중국3 | B7: =SUMIFS(Sheet1!F$4:F$1000,Sheet1!$A$4:$A$1000,">="&Report_P1!$K$5,Sheet1!$A$4:$A$1000,"<="&Report_P1!$K$6,Sheet1!$B$4:$B$1000,"계획",Sheet1!$C$4:$C$1000,"판매량") -> 16 | C7: =SUMIFS(Sheet1!F$4:F$1000,Sheet1!$A$4:$A$1000,">="&Report_P1!$K$5,Sheet1!$A$4:$A$1000,"<="&Report_P1!$K$6,Sheet1!$B$4:$B$1000,"계획",Sheet1!$C$4:$C$1000,"매출액") -> 16 | D7: =SUMIFS(Sheet1!F$4:F$1000,Sheet1!$A$4:$A$1000,">="&Report_P1!$K$5,Sheet1!$A$4:$A$1000,"<="&Report_P1!$K$6,Sheet1!$B$4:$B$1000,"계획",Sheet1!$C$4:$C$1000,"경상이익") -> 2 | E7: =SUMIFS(Sheet1!F$4:F$1000,Sheet1!$A$4:$A$1000,">="&Report_P1!$K$5,Sheet1!$A$4:$A$1000,"<="&Report_P1!$K$6,Sheet1!$B$4:$B$1000,"실적",Sheet1!$C$4:$C$1000,"판매량") -> 17 | F7: =SUMIFS(Sheet1!F$4:F$1000,Sheet1!$A$4:$A$1000,">="&Report_P1!$K$5,Sheet1!$A$4:$A$1000,"<="&Report_P1!$K$6,Sheet1!$B$4:$B$1000,"실적",Sheet1!$C$4:$C$1000,"매출액") -> 14 | G7: =SUMIFS(Sheet1!F$4:F$1000,Sheet1!$A$4:$A$1000,">="&Report_P1!$K$5,Sheet1!$A$4:$A$1000,"<="&Report_P1!$K$6,Sheet1!$B$4:$B$1000,"실적",Sheet1!$C$4:$C$1000,"경상이익") -> 2 | H7: =G7-D7 -> 0
A8: 중국4 | B8: =SUMIFS(Sheet1!G$4:G$1000,Sheet1!$A$4:$A$1000,">="&Report_P1!$K$5,Sheet1!$A$4:$A$1000,"<="&Report_P1!$K$6,Sheet1!$B$4:$B$1000,"계획",Sheet1!$C$4:$C$1000,"판매량") -> 8 | C8: =SUMIFS(Sheet1!G$4:G$1000,Sheet1!$A$4:$A$1000,">="&Report_P1!$K$5,Sheet1!$A$4:$A$1000,"<="&Report_P1!$K$6,Sheet1!$B$4:$B$1000,"계획",Sheet1!$C$4:$C$1000,"매출액") -> 8 | D8: =SUMIFS(Sheet1!G$4:G$1000,Sheet1!$A$4:$A$1000,">="&Report_P1!$K$5,Sheet1!$A$4:$A$1000,"<="&Report_P1!$K$6,Sheet1!$B$4:$B$1000,"계획",Sheet1!$C$4:$C$1000,"경상이익") -> -2 | E8: =SUMIFS(Sheet1!G$4:G$1000,Sheet1!$A$4:$A$1000,">="&Report_P1!$K$5,Sheet1!$A$4:$A$1000,"<="&Report_P1!$K$6,Sheet1!$B$4:$B$1000,"실적",Sheet1!$C$4:$C$1000,"판매량") -> 8 | F8: =SUMIFS(Sheet1!G$4:G$1000,Sheet1!$A$4:$A$1000,">="&Report_P1!$K$5,Sheet1!$A$4:$A$1000,"<="&Report_P1!$K$6,Sheet1!$B$4:$B$1000,"실적",Sheet1!$C$4:$C$1000,"매출액") -> 8 | G8: =SUMIFS(Sheet1!G$4:G$1000,Sheet1!$A$4:$A$1000,">="&Report_P1!$K$5,Sheet1!$A$4:$A$1000,"<="&Report_P1!$K$6,Sheet1!$B$4:$B$1000,"실적",Sheet1!$C$4:$C$1000,"경상이익") -> 0 | H8: =G8-D8 -> 2
A9: 인도1 | B9: =SUMIFS(Sheet1!H$4:H$1000,Sheet1!$A$4:$A$1000,">="&Report_P1!$K$5,Sheet1!$A$4:$A$1000,"<="&Report_P1!$K$6,Sheet1!$B$4:$B$1000,"계획",Sheet1!$C$4:$C$1000,"판매량") -> 16 | C9: =SUMIFS(Sheet1!H$4:H$1000,Sheet1!$A$4:$A$1000,">="&Report_P1!$K$5,Sheet1!$A$4:$A$1000,"<="&Report_P1!$K$6,Sheet1!$B$4:$B$1000,"계획",Sheet1!$C$4:$C$1000,"매출액") -> 16 | D9: =SUMIFS(Sheet1!H$4:H$1000,Sheet1!$A$4:$A$1000,">="&Report_P1!$K$5,Sheet1!$A$4:$A$1000,"<="&Report_P1!$K$6,Sheet1!$B$4:$B$1000,"계획",Sheet1!$C$4:$C$1000,"경상이익") -> 2 | E9: =SUMIFS(Sheet1!H$4:H$1000,Sheet1!$A$4:$A$1000,">="&Report_P1!$K$5,Sheet1!$A$4:$A$1000,"<="&Report_P1!$K$6,Sheet1!$B$4:$B$1000,"실적",Sheet1!$C$4:$C$1000,"판매량") -> 12 | F9: =SUMIFS(Sheet1!H$4:H$1000,Sheet1!$A$4:$A$1000,">="&Report_P1!$K$5,Sheet1!$A$4:$A$1000,"<="&Report_P1!$K$6,Sheet1!$B$4:$B$1000,"실적",Sheet1!$C$4:$C$1000,"매출액") -> 18 | G9: =SUMIFS(Sheet1!H$4:H$1000,Sheet1!$A$4:$A$1000,">="&Report_P1!$K$5,Sheet1!$A$4:$A$1000,"<="&Report_P1!$K$6,Sheet1!$B$4:$B$1000,"실적",Sheet1!$C$4:$C$1000,"경상이익") -> 1 | H9: =G9-D9 -> -1
A10: 인도2 | B10: =SUMIFS(Sheet1!I$4:I$1000,Sheet1!$A$4:$A$1000,">="&Report_P1!$K$5,Sheet1!$A$4:$A$1000,"<="&Report_P1!$K$6,Sheet1!$B$4:$B$1000,"계획",Sheet1!$C$4:$C$1000,"판매량") -> 16 | C10: =SUMIFS(Sheet1!I$4:I$1000,Sheet1!$A$4:$A$1000,">="&Report_P1!$K$5,Sheet1!$A$4:$A$1000,"<="&Report_P1!$K$6,Sheet1!$B$4:$B$1000,"계획",Sheet1!$C$4:$C$1000,"매출액") -> 16 | D10: =SUMIFS(Sheet1!I$4:I$1000,Sheet1!$A$4:$A$1000,">="&Report_P1!$K$5,Sheet1!$A$4:$A$1000,"<="&Report_P1!$K$6,Sheet1!$B$4:$B$1000,"계획",Sheet1!$C$4:$C$1000,"경상이익") -> 2 | E10: =SUMIFS(Sheet1!I$4:I$1000,Sheet1!$A$4:$A$1000,">="&Report_P1!$K$5,Sheet1!$A$4:$A$1000,"<="&Report_P1!$K$6,Sheet1!$B$4:$B$1000,"실적",Sheet1!$C$4:$C$1000,"판매량") -> 12 | F10: =SUMIFS(Sheet1!I$4:I$1000,Sheet1!$A$4:$A$1000,">="&Report_P1!$K$5,Sheet1!$A$4:$A$1000,"<="&Report_P1!$K$6,Sheet1!$B$4:$B$1000,"실적",Sheet1!$C$4:$C$1000,"매출액") -> 18 | G10: =SUMIFS(Sheet1!I$4:I$1000,Sheet1!$A$4:$A$1000,">="&Report_P1!$K$5,Sheet1!$A$4:$A$1000,"<="&Report_P1!$K$6,Sheet1!$B$4:$B$1000,"실적",Sheet1!$C$4:$C$1000,"경상이익") -> 1 | H10: =G10-D10 -> -1
A11: 인도3 | B11: =SUMIFS(Sheet1!J$4:J$1000,Sheet1!$A$4:$A$1000,">="&Report_P1!$K$5,Sheet1!$A$4:$A$1000,"<="&Report_P1!$K$6,Sheet1!$B$4:$B$1000,"계획",Sheet1!$C$4:$C$1000,"판매량") -> 16 | C11: =SUMIFS(Sheet1!J$4:J$1000,Sheet1!$A$4:$A$1000,">="&Report_P1!$K$5,Sheet1!$A$4:$A$1000,"<="&Report_P1!$K$6,Sheet1!$B$4:$B$1000,"계획",Sheet1!$C$4:$C$1000,"매출액") -> 16 | D11: =SUMIFS(Sheet1!J$4:J$1000,Sheet1!$A$4:$A$1000,">="&Report_P1!$K$5,Sheet1!$A$4:$A$1000,"<="&Report_P1!$K$6,Sheet1!$B$4:$B$1000,"계획",Sheet1!$C$4:$C$1000,"경상이익") -> 2 | E11: =SUMIFS(Sheet1!J$4:J$1000,Sheet1!$A$4:$A$1000,">="&Report_P1!$K$5,Sheet1!$A$4:$A$1000,"<="&Report_P1!$K$6,Sheet1!$B$4:$B$1000,"실적",Sheet1!$C$4:$C$1000,"판매량") -> 12 | F11: =SUMIFS(Sheet1!J$4:J$1000,Sheet1!$A$4:$A$1000,">="&Report_P1!$K$5,Sheet1!$A$4:$A$1000,"<="&Report_P1!$K$6,Sheet1!$B$4:$B$1000,"실적",Sheet1!$C$4:$C$1000,"매출액") -> 18 | G11: =SUMIFS(Sheet1!J$4:J$1000,Sheet1!$A$4:$A$1000,">="&Report_P1!$K$5,Sheet1!$A$4:$A$1000,"<="&Report_P1!$K$6,Sheet1!$B$4:$B$1000,"실적",Sheet1!$C$4:$C$1000,"경상이익") -> 1 | H11: =G11-D11 -> -1
A12: 유럽1 | B12: =SUMIFS(Sheet1!K$4:K$1000,Sheet1!$A$4:$A$1000,">="&Report_P1!$K$5,Sheet1!$A$4:$A$1000,"<="&Report_P1!$K$6,Sheet1!$B$4:$B$1000,"계획",Sheet1!$C$4:$C$1000,"판매량") -> 16 | C12: =SUMIFS(Sheet1!K$4:K$1000,Sheet1!$A$4:$A$1000,">="&Report_P1!$K$5,Sheet1!$A$4:$A$1000,"<="&Report_P1!$K$6,Sheet1!$B$4:$B$1000,"계획",Sheet1!$C$4:$C$1000,"매출액") -> 16 | D12: =SUMIFS(Sheet1!K$4:K$1000,Sheet1!$A$4:$A$1000,">="&Report_P1!$K$5,Sheet1!$A$4:$A$1000,"<="&Report_P1!$K$6,Sheet1!$B$4:$B$1000,"계획",Sheet1!$C$4:$C$1000,"경상이익") -> 2 | E12: =SUMIFS(Sheet1!K$4:K$1000,Sheet1!$A$4:$A$1000,">="&Report_P1!$K$5,Sheet1!$A$4:$A$1000,"<="&Report_P1!$K$6,Sheet1!$B$4:$B$1000,"실적",Sheet1!$C$4:$C$1000,"판매량") -> 18 | F12: =SUMIFS(Sheet1!K$4:K$1000,Sheet1!$A$4:$A$1000,">="&Report_P1!$K$5,Sheet1!$A$4:$A$1000,"<="&Report_P1!$K$6,Sheet1!$B$4:$B$1000,"실적",Sheet1!$C$4:$C$1000,"매출액") -> 16 | G12: =SUMIFS(Sheet1!K$4:K$1000,Sheet1!$A$4:$A$1000,">="&Report_P1!$K$5,Sheet1!$A$4:$A$1000,"<="&Report_P1!$K$6,Sheet1!$B$4:$B$1000,"실적",Sheet1!$C$4:$C$1000,"경상이익") -> -2 | H12: =G12-D12 -> -4
A13: 유럽2 | B13: =SUMIFS(Sheet1!L$4:L$1000,Sheet1!$A$4:$A$1000,">="&Report_P1!$K$5,Sheet1!$A$4:$A$1000,"<="&Report_P1!$K$6,Sheet1!$B$4:$B$1000,"계획",Sheet1!$C$4:$C$1000,"판매량") -> 16 | C13: =SUMIFS(Sheet1!L$4:L$1000,Sheet1!$A$4:$A$1000,">="&Report_P1!$K$5,Sheet1!$A$4:$A$1000,"<="&Report_P1!$K$6,Sheet1!$B$4:$B$1000,"계획",Sheet1!$C$4:$C$1000,"매출액") -> 16 | D13: =SUMIFS(Sheet1!L$4:L$1000,Sheet1!$A$4:$A$1000,">="&Report_P1!$K$5,Sheet1!$A$4:$A$1000,"<="&Report_P1!$K$6,Sheet1!$B$4:$B$1000,"계획",Sheet1!$C$4:$C$1000,"경상이익") -> 2 | E13: =SUMIFS(Sheet1!L$4:L$1000,Sheet1!$A$4:$A$1000,">="&Report_P1!$K$5,Sheet1!$A$4:$A$1000,"<="&Report_P1!$K$6,Sheet1!$B$4:$B$1000,"실적",Sheet1!$C$4:$C$1000,"판매량") -> 18 | F13: =SUMIFS(Sheet1!L$4:L$1000,Sheet1!$A$4:$A$1000,">="&Report_P1!$K$5,Sheet1!$A$4:$A$1000,"<="&Report_P1!$K$6,Sheet1!$B$4:$B$1000,"실적",Sheet1!$C$4:$C$1000,"매출액") -> 16 | G13: =SUMIFS(Sheet1!L$4:L$1000,Sheet1!$A$4:$A$1000,">="&Report_P1!$K$5,Sheet1!$A$4:$A$1000,"<="&Report_P1!$K$6,Sheet1!$B$4:$B$1000,"실적",Sheet1!$C$4:$C$1000,"경상이익") -> -2 | H13: =G13-D13 -> -4
A14: 유럽3 | B14: =SUMIFS(Sheet1!M$4:M$1000,Sheet1!$A$4:$A$1000,">="&Report_P1!$K$5,Sheet1!$A$4:$A$1000,"<="&Report_P1!$K$6,Sheet1!$B$4:$B$1000,"계획",Sheet1!$C$4:$C$1000,"판매량") -> 16 | C14: =SUMIFS(Sheet1!M$4:M$1000,Sheet1!$A$4:$A$1000,">="&Report_P1!$K$5,Sheet1!$A$4:$A$1000,"<="&Report_P1!$K$6,Sheet1!$B$4:$B$1000,"계획",Sheet1!$C$4:$C$1000,"매출액") -> 16 | D14: =SUMIFS(Sheet1!M$4:M$1000,Sheet1!$A$4:$A$1000,">="&Report_P1!$K$5,Sheet1!$A$4:$A$1000,"<="&Report_P1!$K$6,Sheet1!$B$4:$B$1000,"계획",Sheet1!$C$4:$C$1000,"경상이익") -> 2 | E14: =SUMIFS(Sheet1!M$4:M$1000,Sheet1!$A$4:$A$1000,">="&Report_P1!$K$5,Sheet1!$A$4:$A$1000,"<="&Report_P1!$K$6,Sheet1!$B$4:$B$1000,"실적",Sheet1!$C$4:$C$1000,"판매량") -> 0 | F14: =SUMIFS(Sheet1!M$4:M$1000,Sheet1!$A$4:$A$1000,">="&Report_P1!$K$5,Sheet1!$A$4:$A$1000,"<="&Report_P1!$K$6,Sheet1!$B$4:$B$1000,"실적",Sheet1!$C$4:$C$1000,"매출액") -> 0 | G14: =SUMIFS(Sheet1!M$4:M$1000,Sheet1!$A$4:$A$1000,">="&Report_P1!$K$5,Sheet1!$A$4:$A$1000,"<="&Report_P1!$K$6,Sheet1!$B$4:$B$1000,"실적",Sheet1!$C$4:$C$1000,"경상이익") -> 1 | H14: =G14-D14 -> -1
A15: 유럽4 | B15: =SUMIFS(Sheet1!N$4:N$1000,Sheet1!$A$4:$A$1000,">="&Report_P1!$K$5,Sheet1!$A$4:$A$1000,"<="&Report_P1!$K$6,Sheet1!$B$4:$B$1000,"계획",Sheet1!$C$4:$C$1000,"판매량") -> 16 | C15: =SUMIFS(Sheet1!N$4:N$1000,Sheet1!$A$4:$A$1000,">="&Report_P1!$K$5,Sheet1!$A$4:$A$1000,"<="&Report_P1!$K$6,Sheet1!$B$4:$B$1000,"계획",Sheet1!$C$4:$C$1000,"매출액") -> 16 | D15: =SUMIFS(Sheet1!N$4:N$1000,Sheet1!$A$4:$A$1000,">="&Report_P1!$K$5,Sheet1!$A$4:$A$1000,"<="&Report_P1!$K$6,Sheet1!$B$4:$B$1000,"계획",Sheet1!$C$4:$C$1000,"경상이익") -> 2 | E15: =SUMIFS(Sheet1!N$4:N$1000,Sheet1!$A$4:$A$1000,">="&Report_P1!$K$5,Sheet1!$A$4:$A$1000,"<="&Report_P1!$K$6,Sheet1!$B$4:$B$1000,"실적",Sheet1!$C$4:$C$1000,"판매량") -> 18 | F15: =SUMIFS(Sheet1!N$4:N$1000,Sheet1!$A$4:$A$1000,">="&Report_P1!$K$5,Sheet1!$A$4:$A$1000,"<="&Report_P1!$K$6,Sheet1!$B$4:$B$1000,"실적",Sheet1!$C$4:$C$1000,"매출액") -> 16 | G15: =SUMIFS(Sheet1!N$4:N$1000,Sheet1!$A$4:$A$1000,">="&Report_P1!$K$5,Sheet1!$A$4:$A$1000,"<="&Report_P1!$K$6,Sheet1!$B$4:$B$1000,"실적",Sheet1!$C$4:$C$1000,"경상이익") -> -2 | H15: =G15-D15 -> -4
A16: 미주1 | B16: =SUMIFS(Sheet1!O$4:O$1000,Sheet1!$A$4:$A$1000,">="&Report_P1!$K$5,Sheet1!$A$4:$A$1000,"<="&Report_P1!$K$6,Sheet1!$B$4:$B$1000,"계획",Sheet1!$C$4:$C$1000,"판매량") -> 16 | C16: =SUMIFS(Sheet1!O$4:O$1000,Sheet1!$A$4:$A$1000,">="&Report_P1!$K$5,Sheet1!$A$4:$A$1000,"<="&Report_P1!$K$6,Sheet1!$B$4:$B$1000,"계획",Sheet1!$C$4:$C$1000,"매출액") -> 16 | D16: =SUMIFS(Sheet1!O$4:O$1000,Sheet1!$A$4:$A$1000,">="&Report_P1!$K$5,Sheet1!$A$4:$A$1000,"<="&Report_P1!$K$6,Sheet1!$B$4:$B$1000,"계획",Sheet1!$C$4:$C$1000,"경상이익") -> 2 | E16: =SUMIFS(Sheet1!O$4:O$1000,Sheet1!$A$4:$A$1000,">="&Report_P1!$K$5,Sheet1!$A$4:$A$1000,"<="&Report_P1!$K$6,Sheet1!$B$4:$B$1000,"실적",Sheet1!$C$4:$C$1000,"판매량") -> 24 | F16: =SUMIFS(Sheet1!O$4:O$1000,Sheet1!$A$4:$A$1000,">="&Report_P1!$K$5,Sheet1!$A$4:$A$1000,"<="&Report_P1!$K$6,Sheet1!$B$4:$B$1000,"실적",Sheet1!$C$4:$C$1000,"매출액") -> 36 | G16: =SUMIFS(Sheet1!O$4:O$1000,Sheet1!$A$4:$A$1000,">="&Report_P1!$K$5,Sheet1!$A$4:$A$1000,"<="&Report_P1!$K$6,Sheet1!$B$4:$B$1000,"실적",Sheet1!$C$4:$C$1000,"경상이익") -> 2 | H16: =G16-D16 -> 0
A17: 미주2 | B17: =SUMIFS(Sheet1!P$4:P$1000,Sheet1!$A$4:$A$1000,">="&Report_P1!$K$5,Sheet1!$A$4:$A$1000,"<="&Report_P1!$K$6,Sheet1!$B$4:$B$1000,"계획",Sheet1!$C$4:$C$1000,"판매량") -> 16 | C17: =SUMIFS(Sheet1!P$4:P$1000,Sheet1!$A$4:$A$1000,">="&Report_P1!$K$5,Sheet1!$A$4:$A$1000,"<="&Report_P1!$K$6,Sheet1!$B$4:$B$1000,"계획",Sheet1!$C$4:$C$1000,"매출액") -> 16 | D17: =SUMIFS(Sheet1!P$4:P$1000,Sheet1!$A$4:$A$1000,">="&Report_P1!$K$5,Sheet1!$A$4:$A$1000,"<="&Report_P1!$K$6,Sheet1!$B$4:$B$1000,"계획",Sheet1!$C$4:$C$1000,"경상이익") -> 2 | E17: =SUMIFS(Sheet1!P$4:P$1000,Sheet1!$A$4:$A$1000,">="&Report_P1!$K$5,Sheet1!$A$4:$A$1000,"<="&Report_P1!$K$6,Sheet1!$B$4:$B$1000,"실적",Sheet1!$C$4:$C$1000,"판매량") -> 24 | F17: =SUMIFS(Sheet1!P$4:P$1000,Sheet1!$A$4:$A$1000,">="&Report_P1!$K$5,Sheet1!$A$4:$A$1000,"<="&Report_P1!$K$6,Sheet1!$B$4:$B$1000,"실적",Sheet1!$C$4:$C$1000,"매출액") -> 36 | G17: =SUMIFS(Sheet1!P$4:P$1000,Sheet1!$A$4:$A$1000,">="&Report_P1!$K$5,Sheet1!$A$4:$A$1000,"<="&Report_P1!$K$6,Sheet1!$B$4:$B$1000,"실적",Sheet1!$C$4:$C$1000,"경상이익") -> 2 | H17: =G17-D17 -> 0
A18: 미주3 | B18: =SUMIFS(Sheet1!Q$4:Q$1000,Sheet1!$A$4:$A$1000,">="&Report_P1!$K$5,Sheet1!$A$4:$A$1000,"<="&Report_P1!$K$6,Sheet1!$B$4:$B$1000,"계획",Sheet1!$C$4:$C$1000,"판매량") -> 16 | C18: =SUMIFS(Sheet1!Q$4:Q$1000,Sheet1!$A$4:$A$1000,">="&Report_P1!$K$5,Sheet1!$A$4:$A$1000,"<="&Report_P1!$K$6,Sheet1!$B$4:$B$1000,"계획",Sheet1!$C$4:$C$1000,"매출액") -> 16 | D18: =SUMIFS(Sheet1!Q$4:Q$1000,Sheet1!$A$4:$A$1000,">="&Report_P1!$K$5,Sheet1!$A$4:$A$1000,"<="&Report_P1!$K$6,Sheet1!$B$4:$B$1000,"계획",Sheet1!$C$4:$C$1000,"경상이익") -> 2 | E18: =SUMIFS(Sheet1!Q$4:Q$1000,Sheet1!$A$4:$A$1000,">="&Report_P1!$K$5,Sheet1!$A$4:$A$1000,"<="&Report_P1!$K$6,Sheet1!$B$4:$B$1000,"실적",Sheet1!$C$4:$C$1000,"판매량") -> 24 | F18: =SUMIFS(Sheet1!Q$4:Q$1000,Sheet1!$A$4:$A$1000,">="&Report_P1!$K$5,Sheet1!$A$4:$A$1000,"<="&Report_P1!$K$6,Sheet1!$B$4:$B$1000,"실적",Sheet1!$C$4:$C$1000,"매출액") -> 36 | G18: =SUMIFS(Sheet1!Q$4:Q$1000,Sheet1!$A$4:$A$1000,">="&Report_P1!$K$5,Sheet1!$A$4:$A$1000,"<="&Report_P1!$K$6,Sheet1!$B$4:$B$1000,"실적",Sheet1!$C$4:$C$1000,"경상이익") -> 2 | H18: =G18-D18 -> 0
A19: 미주4 | B19: =SUMIFS(Sheet1!R$4:R$1000,Sheet1!$A$4:$A$1000,">="&Report_P1!$K$5,Sheet1!$A$4:$A$1000,"<="&Report_P1!$K$6,Sheet1!$B$4:$B$1000,"계획",Sheet1!$C$4:$C$1000,"판매량") -> 16 | C19: =SUMIFS(Sheet1!R$4:R$1000,Sheet1!$A$4:$A$1000,">="&Report_P1!$K$5,Sheet1!$A$4:$A$1000,"<="&Report_P1!$K$6,Sheet1!$B$4:$B$1000,"계획",Sheet1!$C$4:$C$1000,"매출액") -> 16 | D19: =SUMIFS(Sheet1!R$4:R$1000,Sheet1!$A$4:$A$1000,">="&Report_P1!$K$5,Sheet1!$A$4:$A$1000,"<="&Report_P1!$K$6,Sheet1!$B$4:$B$1000,"계획",Sheet1!$C$4:$C$1000,"경상이익") -> 2 | E19: =SUMIFS(Sheet1!R$4:R$1000,Sheet1!$A$4:$A$1000,">="&Report_P1!$K$5,Sheet1!$A$4:$A$1000,"<="&Report_P1!$K$6,Sheet1!$B$4:$B$1000,"실적",Sheet1!$C$4:$C$1000,"판매량") -> 24 | F19: =SUMIFS(Sheet1!R$4:R$1000,Sheet1!$A$4:$A$1000,">="&Report_P1!$K$5,Sheet1!$A$4:$A$1000,"<="&Report_P1!$K$6,Sheet1!$B$4:$B$1000,"실적",Sheet1!$C$4:$C$1000,"매출액") -> 36 | G19: =SUMIFS(Sheet1!R$4:R$1000,Sheet1!$A$4:$A$1000,">="&Report_P1!$K$5,Sheet1!$A$4:$A$1000,"<="&Report_P1!$K$6,Sheet1!$B$4:$B$1000,"실적",Sheet1!$C$4:$C$1000,"경상이익") -> 2 | H19: =G19-D19 -> 0
A20: 합계 | B20: =SUM(B5:B19) -> 232 | C20: =SUM(C5:C19) -> 232 | D20: =SUM(D5:D19) -> 26 | E20: =SUM(E5:E19) -> 245 | F20: =SUM(F5:F19) -> 296 | G20: =SUM(G5:G19) -> 12 | H20: =SUM(H5:H19) -> -14

Sheet Report_P2
A1: 해외법인 손익 리포트 - 경상이익 차이 및 주요 차이내역 (Page 2)
A2: 기준월 선택: | B2: =Report_P1!B2 -> 2026-02 누계
A4: 법인 | B4: 경상이익차이 | C4: 물량차이 | D4: 롤마진차이 | E4: 제경비차이 | F4: 영업외차이 | G4: 검증(차이내역합-경상이익차이)
A5: 중국1 | B5: =Report_P1!G5-Report_P1!D5 -> 0 | C5: =Calc!B16*(Calc!B3-Calc!B2) -> 0.625 | D5: =(Calc!B17-Calc!B16)*Calc!B3 -> 0.375 | E5: =Calc!B18-Calc!B19 -> -4 | F5: =Calc!B15-Calc!B14 -> 3 | G5: =ROUND(C5+D5+E5+F5-B5,6) -> 0
A6: 중국2 | B6: =Report_P1!G6-Report_P1!D6 -> 0 | C6: =Calc!C16*(Calc!C3-Calc!C2) -> 0.625 | D6: =(Calc!C17-Calc!C16)*Calc!C3 -> 0.375 | E6: =Calc!C18-Calc!C19 -> -4 | F6: =Calc!C15-Calc!C14 -> 3 | G6: =ROUND(C6+D6+E6+F6-B6,6) -> 0
A7: 중국3 | B7: =Report_P1!G7-Report_P1!D7 -> 0 | C7: =Calc!D16*(Calc!D3-Calc!D2) -> 0.625 | D7: =(Calc!D17-Calc!D16)*Calc!D3 -> 0.375 | E7: =Calc!D18-Calc!D19 -> -4 | F7: =Calc!D15-Calc!D14 -> 3 | G7: =ROUND(C7+D7+E7+F7-B7,6) -> 0
A8: 중국4 | B8: =Report_P1!G8-Report_P1!D8 -> 2 | C8: =Calc!E16*(Calc!E3-Calc!E2) -> 0 | D8: =(Calc!E17-Calc!E16)*Calc!E3 -> 0 | E8: =Calc!E18-Calc!E19 -> -2 | F8: =Calc!E15-Calc!E14 -> 4 | G8: =ROUND(C8+D8+E8+F8-B8,6) -> 0
A9: 인도1 | B9: =Report_P1!G9-Report_P1!D9 -> -1 | C9: =Calc!F16*(Calc!F3-Calc!F2) -> -2.5 | D9: =(Calc!F17-Calc!F16)*Calc!F3 -> 1.5 | E9: =Calc!F18-Calc!F19 -> 1 | F9: =Calc!F15-Calc!F14 -> -1 | G9: =ROUND(C9+D9+E9+F9-B9,6) -> 0
A10: 인도2 | B10: =Report_P1!G10-Report_P1!D10 -> -1 | C10: =Calc!G16*(Calc!G3-Calc!G2) -> -2.5 | D10: =(Calc!G17-Calc!G16)*Calc!G3 -> 1.5 | E10: =Calc!G18-Calc!G19 -> 1 | F10: =Calc!G15-Calc!G14 -> -1 | G10: =ROUND(C10+D10+E10+F10-B10,6) -> 0
A11: 인도3 | B11: =Report_P1!G11-Report_P1!D11 -> -1 | C11: =Calc!H16*(Calc!H3-Calc!H2) -> -2.5 | D11: =(Calc!H17-Calc!H16)*Calc!H3 -> 1.5 | E11: =Calc!H18-Calc!H19 -> 1 | F11: =Calc!H15-Calc!H14 -> -1 | G11: =ROUND(C11+D11+E11+F11-B11,6) -> 0
A12: 유럽1 | B12: =Report_P1!G12-Report_P1!D12 -> -4 | C12: =Calc!I16*(Calc!I3-Calc!I2) -> 1.25 | D12: =(Calc!I17-Calc!I16)*Calc!I3 -> -3.25 | E12: =Calc!I18-Calc!I19 -> 0 | F12: =Calc!I15-Calc!I14 -> -2 | G12: =ROUND(C12+D12+E12+F12-B12,6) -> 0
A13: 유럽2 | B13: =Report_P1!G13-Report_P1!D13 -> -4 | C13: =Calc!J16*(Calc!J3-Calc!J2) -> 1.25 | D13: =(Calc!J17-Calc!J16)*Calc!J3 -> -3.25 | E13: =Calc!J18-Calc!J19 -> 0 | F13: =Calc!J15-Calc!J14 -> -2 | G13: =ROUND(C13+D13+E13+F13-B13,6) -> 0
A14: 유럽3 | B14: =Report_P1!G14-Report_P1!D14 -> -1 | C14: =Calc!K16*(Calc!K3-Calc!K2) -> -10 | D14: =(Calc!K17-Calc!K16)*Calc!K3 -> 0 | E14: =Calc!K18-Calc!K19 -> 4 | F14: =Calc!K15-Calc!K14 -> 5 | G14: =ROUND(C14+D14+E14+F14-B14,6) -> 0
A15: 유럽4 | B15: =Report_P1!G15-Report_P1!D15 -> -4 | C15: =Calc!L16*(Calc!L3-Calc!L2) -> 1.25 | D15: =(Calc!L17-Calc!L16)*Calc!L3 -> -3.25 | E15: =Calc!L18-Calc!L19 -> 0 | F15: =Calc!L15-Calc!L14 -> -2 | G15: =ROUND(C15+D15+E15+F15-B15,6) -> 0
A16: 미주1 | B16: =Report_P1!G16-Report_P1!D16 -> 0 | C16: =Calc!M16*(Calc!M3-Calc!M2) -> 5 | D16: =(Calc!M17-Calc!M16)*Calc!M3 -> 1 | E16: =Calc!M18-Calc!M19 -> -3 | F16: =Calc!M15-Calc!M14 -> -3 | G16: =ROUND(C16+D16+E16+F16-B16,6) -> 0
A17: 미주2 | B17: =Report_P1!G17-Report_P1!D17 -> 0 | C17: =Calc!N16*(Calc!N3-Calc!N2) -> 5 | D17: =(Calc!N17-Calc!N16)*Calc!N3 -> 1 | E17: =Calc!N18-Calc!N19 -> -3 | F17: =Calc!N15-Calc!N14 -> -3 | G17: =ROUND(C17+D17+E17+F17-B17,6) -> 0
A18: 미주3 | B18: =Report_P1!G18-Report_P1!D18 -> 0 | C18: =Calc!O16*(Calc!O3-Calc!O2) -> 5 | D18: =(Calc!O17-Calc!O16)*Calc!O3 -> 1 | E18: =Calc!O18-Calc!O19 -> -3 | F18: =Calc!O15-Calc!O14 -> -3 | G18: =ROUND(C18+D18+E18+F18-B18,6) -> 0
A19: 미주4 | B19: =Report_P1!G19-Report_P1!D19 -> 0 | C19: =Calc!P16*(Calc!P3-Calc!P2) -> 5 | D19: =(Calc!P17-Calc!P16)*Calc!P3 -> 1 | E19: =Calc!P18-Calc!P19 -> -3 | F19: =Calc!P15-Calc!P14 -> -3 | G19: =ROUND(C19+D19+E19+F19-B19,6) -> 0
A20: 합계 | B20: =SUM(B5:B19) -> -14 | C20: =SUM(C5:C19) -> 8.125 | D20: =SUM(D5:D19) -> -0.125 | E20: =SUM(E5:E19) -> -19 | F20: =SUM(F5:F19) -> -3 | G20: =ROUND(C20+D20+E20+F20-B20,6) -> 0

Sheet Calc
A1: 구분 | B1: 중국1 | C1: 중국2 | D1: 중국3 | E1: 중국4 | F1: 인도1 | G1: 인도2 | H1: 인도3 | I1: 유럽1 | J1: 유럽2 | K1: 유럽3 | L1: 유럽4 | M1: 미주1 | N1: 미주2 | O1: 미주3 | P1: 미주4
A2: 계획판매량 | B2: =SUMIFS(Sheet1!D$4:D$1000,Sheet1!$A$4:$A$1000,">="&Report_P1!$K$5,Sheet1!$A$4:$A$1000,"<="&Report_P1!$K$6,Sheet1!$B$4:$B$1000,"계획",Sheet1!$C$4:$C$1000,"판매량") -> 16 | C2: =SUMIFS(Sheet1!E$4:E$1000,Sheet1!$A$4:$A$1000,">="&Report_P1!$K$5,Sheet1!$A$4:$A$1000,"<="&Report_P1!$K$6,Sheet1!$B$4:$B$1000,"계획",Sheet1!$C$4:$C$1000,"판매량") -> 16 | D2: =SUMIFS(Sheet1!F$4:F$1000,Sheet1!$A$4:$A$1000,">="&Report_P1!$K$5,Sheet1!$A$4:$A$1000,"<="&Report_P1!$K$6,Sheet1!$B$4:$B$1000,"계획",Sheet1!$C$4:$C$1000,"판매량") -> 16 | E2: =SUMIFS(Sheet1!G$4:G$1000,Sheet1!$A$4:$A$1000,">="&Report_P1!$K$5,Sheet1!$A$4:$A$1000,"<="&Report_P1!$K$6,Sheet1!$B$4:$B$1000,"계획",Sheet1!$C$4:$C$1000,"판매량") -> 8 | F2: =SUMIFS(Sheet1!H$4:H$1000,Sheet1!$A$4:$A$1000,">="&Report_P1!$K$5,Sheet1!$A$4:$A$1000,"<="&Report_P1!$K$6,Sheet1!$B$4:$B$1000,"계획",Sheet1!$C$4:$C$1000,"판매량") -> 16 | G2: =SUMIFS(Sheet1!I$4:I$1000,Sheet1!$A$4:$A$1000,">="&Report_P1!$K$5,Sheet1!$A$4:$A$1000,"<="&Report_P1!$K$6,Sheet1!$B$4:$B$1000,"계획",Sheet1!$C$4:$C$1000,"판매량") -> 16 | H2: =SUMIFS(Sheet1!J$4:J$1000,Sheet1!$A$4:$A$1000,">="&Report_P1!$K$5,Sheet1!$A$4:$A$1000,"<="&Report_P1!$K$6,Sheet1!$B$4:$B$1000,"계획",Sheet1!$C$4:$C$1000,"판매량") -> 16 | I2: =SUMIFS(Sheet1!K$4:K$1000,Sheet1!$A$4:$A$1000,">="&Report_P1!$K$5,Sheet1!$A$4:$A$1000,"<="&Report_P1!$K$6,Sheet1!$B$4:$B$1000,"계획",Sheet1!$C$4:$C$1000,"판매량") -> 16 | ... P2: =SUMIFS(Sheet1!R$4:R$1000,Sheet1!$A$4:$A$1000,">="&Report_P1!$K$5,Sheet1!$A$4:$A$1000,"<="&Report_P1!$K$6,Sheet1!$B$4:$B$1000,"계획",Sheet1!$C$4:$C$1000,"판매량") -> 16
A3: 실적판매량 | B3: =SUMIFS(Sheet1!D$4:D$1000,Sheet1!$A$4:$A$1000,">="&Report_P1!$K$5,Sheet1!$A$4:$A$1000,"<="&Report_P1!$K$6,Sheet1!$B$4:$B$1000,"실적",Sheet1!$C$4:$C$1000,"판매량") -> 17 | C3: =SUMIFS(Sheet1!E$4:E$1000,Sheet1!$A$4:$A$1000,">="&Report_P1!$K$5,Sheet1!$A$4:$A$1000,"<="&Report_P1!$K$6,Sheet1!$B$4:$B$1000,"실적",Sheet1!$C$4:$C$1000,"판매량") -> 17 | D3: =SUMIFS(Sheet1!F$4:F$1000,Sheet1!$A$4:$A$1000,">="&Report_P1!$K$5,Sheet1!$A$4:$A$1000,"<="&Report_P1!$K$6,Sheet1!$B$4:$B$1000,"실적",Sheet1!$C$4:$C$1000,"판매량") -> 17 | E3: =SUMIFS(Sheet1!G$4:G$1000,Sheet1!$A$4:$A$1000,">="&Report_P1!$K$5,Sheet1!$A$4:$A$1000,"<="&Report_P1!$K$6,Sheet1!$B$4:$B$1000,"실적",Sheet1!$C$4:$C$1000,"판매량") -> 8 | F3: =SUMIFS(Sheet1!H$4:H$1000,Sheet1!$A$4:$A$1000,">="&Report_P1!$K$5,Sheet1!$A$4:$A$1000,"<="&Report_P1!$K$6,Sheet1!$B$4:$B$1000,"실적",Sheet1!$C$4:$C$1000,"판매량") -> 12 | G3: =SUMIFS(Sheet1!I$4:I$1000,Sheet1!$A$4:$A$1000,">="&Report_P1!$K$5,Sheet1!$A$4:$A$1000,"<="&Report_P1!$K$6,Sheet1!$B$4:$B$1000,"실적",Sheet1!$C$4:$C$1000,"판매량") -> 12 | H3: =SUMIFS(Sheet1!J$4:J$1000,Sheet1!$A$4:$A$1000,">="&Report_P1!$K$5,Sheet1!$A$4:$A$1000,"<="&Report_P1!$K$6,Sheet1!$B$4:$B$1000,"실적",Sheet1!$C$4:$C$1000,"판매량") -> 12 | I3: =SUMIFS(Sheet1!K$4:K$1000,Sheet1!$A$4:$A$1000,">="&Report_P1!$K$5,Sheet1!$A$4:$A$1000,"<="&Report_P1!$K$6,Sheet1!$B$4:$B$1000,"실적",Sheet1!$C$4:$C$1000,"판매량") -> 18 | ... P3: =SUMIFS(Sheet1!R$4:R$1000,Sheet1!$A$4:$A$1000,">="&Report_P1!$K$5,Sheet1!$A$4:$A$1000,"<="&Report_P1!$K$6,Sheet1!$B$4:$B$1000,"실적",Sheet1!$C$4:$C$1000,"판매량") -> 24
A4: 계획매출액 | B4: =SUMIFS(Sheet1!D$4:D$1000,Sheet1!$A$4:$A$1000,">="&Report_P1!$K$5,Sheet1!$A$4:$A$1000,"<="&Report_P1!$K$6,Sheet1!$B$4:$B$1000,"계획",Sheet1!$C$4:$C$1000,"매출액") -> 16 | C4: =SUMIFS(Sheet1!E$4:E$1000,Sheet1!$A$4:$A$1000,">="&Report_P1!$K$5,Sheet1!$A$4:$A$1000,"<="&Report_P1!$K$6,Sheet1!$B$4:$B$1000,"계획",Sheet1!$C$4:$C$1000,"매출액") -> 16 | D4: =SUMIFS(Sheet1!F$4:F$1000,Sheet1!$A$4:$A$1000,">="&Report_P1!$K$5,Sheet1!$A$4:$A$1000,"<="&Report_P1!$K$6,Sheet1!$B$4:$B$1000,"계획",Sheet1!$C$4:$C$1000,"매출액") -> 16 | E4: =SUMIFS(Sheet1!G$4:G$1000,Sheet1!$A$4:$A$1000,">="&Report_P1!$K$5,Sheet1!$A$4:$A$1000,"<="&Report_P1!$K$6,Sheet1!$B$4:$B$1000,"계획",Sheet1!$C$4:$C$1000,"매출액") -> 8 | F4: =SUMIFS(Sheet1!H$4:H$1000,Sheet1!$A$4:$A$1000,">="&Report_P1!$K$5,Sheet1!$A$4:$A$1000,"<="&Report_P1!$K$6,Sheet1!$B$4:$B$1000,"계획",Sheet1!$C$4:$C$1000,"매출액") -> 16 | G4: =SUMIFS(Sheet1!I$4:I$1000,Sheet1!$A$4:$A$1000,">="&Report_P1!$K$5,Sheet1!$A$4:$A$1000,"<="&Report_P1!$K$6,Sheet1!$B$4:$B$1000,"계획",Sheet1!$C$4:$C$1000,"매출액") -> 16 | H4: =SUMIFS(Sheet1!J$4:J$1000,Sheet1!$A$4:$A$1000,">="&Report_P1!$K$5,Sheet1!$A$4:$A$1000,"<="&Report_P1!$K$6,Sheet1!$B$4:$B$1000,"계획",Sheet1!$C$4:$C$1000,"매출액") -> 16 | I4: =SUMIFS(Sheet1!K$4:K$1000,Sheet1!$A$4:$A$1000,">="&Report_P1!$K$5,Sheet1!$A$4:$A$1000,"<="&Report_P1!$K$6,Sheet1!$B$4:$B$1000,"계획",Sheet1!$C$4:$C$1000,"매출액") -> 16 | ... P4: =SUMIFS(Sheet1!R$4:R$1000,Sheet1!$A$4:$A$1000,">="&Report_P1!$K$5,Sheet1!$A$4:$A$1000,"<="&Report_P1!$K$6,Sheet1!$B$4:$B$1000,"계획",Sheet1!$C$4:$C$1000,"매출액") -> 16
A5: 실적매출액 | B5: =SUMIFS(Sheet1!D$4:D$1000,Sheet1!$A$4:$A$1000,">="&Report_P1!$K$5,Sheet1!$A$4:$A$1000,"<="&Report_P1!$K$6,Sheet1!$B$4:$B$1000,"실적",Sheet1!$C$4:$C$1000,"매출액") -> 14 | C5: =SUMIFS(Sheet1!E$4:E$1000,Sheet1!$A$4:$A$1000,">="&Report_P1!$K$5,Sheet1!$A$4:$A$1000,"<="&Report_P1!$K$6,Sheet1!$B$4:$B$1000,"실적",Sheet1!$C$4:$C$1000,"매출액") -> 14 | D5: =SUMIFS(Sheet1!F$4:F$1000,Sheet1!$A$4:$A$1000,">="&Report_P1!$K$5,Sheet1!$A$4:$A$1000,"<="&Report_P1!$K$6,Sheet1!$B$4:$B$1000,"실적",Sheet1!$C$4:$C$1000,"매출액") -> 14 | E5: =SUMIFS(Sheet1!G$4:G$1000,Sheet1!$A$4:$A$1000,">="&Report_P1!$K$5,Sheet1!$A$4:$A$1000,"<="&Report_P1!$K$6,Sheet1!$B$4:$B$1000,"실적",Sheet1!$C$4:$C$1000,"매출액") -> 8 | F5: =SUMIFS(Sheet1!H$4:H$1000,Sheet1!$A$4:$A$1000,">="&Report_P1!$K$5,Sheet1!$A$4:$A$1000,"<="&Report_P1!$K$6,Sheet1!$B$4:$B$1000,"실적",Sheet1!$C$4:$C$1000,"매출액") -> 18 | G5: =SUMIFS(Sheet1!I$4:I$1000,Sheet1!$A$4:$A$1000,">="&Report_P1!$K$5,Sheet1!$A$4:$A$1000,"<="&Report_P1!$K$6,Sheet1!$B$4:$B$1000,"실적",Sheet1!$C$4:$C$1000,"매출액") -> 18 | H5: =SUMIFS(Sheet1!J$4:J$1000,Sheet1!$A$4:$A$1000,">="&Report_P1!$K$5,Sheet1!$A$4:$A$1000,"<="&Report_P1!$K$6,Sheet1!$B$4:$B$1000,"실적",Sheet1!$C$4:$C$1000,"매출액") -> 18 | I5: =SUMIFS(Sheet1!K$4:K$1000,Sheet1!$A$4:$A$1000,">="&Report_P1!$K$5,Sheet1!$A$4:$A$1000,"<="&Report_P1!$K$6,Sheet1!$B$4:$B$1000,"실적",Sheet1!$C$4:$C$1000,"매출액") -> 16 | ... P5: =SUMIFS(Sheet1!R$4:R$1000,Sheet1!$A$4:$A$1000,">="&Report_P1!$K$5,Sheet1!$A$4:$A$1000,"<="&Report_P1!$K$6,Sheet1!$B$4:$B$1000,"실적",Sheet1!$C$4:$C$1000,"매출액") -> 36
A6: 계획재료비 | B6: =SUMIFS(Sheet1!D$4:D$1000,Sheet1!$A$4:$A$1000,">="&Report_P1!$K$5,Sheet1!$A$4:$A$1000,"<="&Report_P1!$K$6,Sheet1!$B$4:$B$1000,"계획",Sheet1!$C$4:$C$1000," - 재료비") -> 6 | C6: =SUMIFS(Sheet1!E$4:E$1000,Sheet1!$A$4:$A$1000,">="&Report_P1!$K$5,Sheet1!$A$4:$A$1000,"<="&Report_P1!$K$6,Sheet1!$B$4:$B$1000,"계획",Sheet1!$C$4:$C$1000," - 재료비") -> 6 | D6: =SUMIFS(Sheet1!F$4:F$1000,Sheet1!$A$4:$A$1000,">="&Report_P1!$K$5,Sheet1!$A$4:$A$1000,"<="&Report_P1!$K$6,Sheet1!$B$4:$B$1000,"계획",Sheet1!$C$4:$C$1000," - 재료비") -> 6 | E6: =SUMIFS(Sheet1!G$4:G$1000,Sheet1!$A$4:$A$1000,">="&Report_P1!$K$5,Sheet1!$A$4:$A$1000,"<="&Report_P1!$K$6,Sheet1!$B$4:$B$1000,"계획",Sheet1!$C$4:$C$1000," - 재료비") -> 6 | F6: =SUMIFS(Sheet1!H$4:H$1000,Sheet1!$A$4:$A$1000,">="&Report_P1!$K$5,Sheet1!$A$4:$A$1000,"<="&Report_P1!$K$6,Sheet1!$B$4:$B$1000,"계획",Sheet1!$C$4:$C$1000," - 재료비") -> 6 | G6: =SUMIFS(Sheet1!I$4:I$1000,Sheet1!$A$4:$A$1000,">="&Report_P1!$K$5,Sheet1!$A$4:$A$1000,"<="&Report_P1!$K$6,Sheet1!$B$4:$B$1000,"계획",Sheet1!$C$4:$C$1000," - 재료비") -> 6 | H6: =SUMIFS(Sheet1!J$4:J$1000,Sheet1!$A$4:$A$1000,">="&Report_P1!$K$5,Sheet1!$A$4:$A$1000,"<="&Report_P1!$K$6,Sheet1!$B$4:$B$1000,"계획",Sheet1!$C$4:$C$1000," - 재료비") -> 6 | I6: =SUMIFS(Sheet1!K$4:K$1000,Sheet1!$A$4:$A$1000,">="&Report_P1!$K$5,Sheet1!$A$4:$A$1000,"<="&Report_P1!$K$6,Sheet1!$B$4:$B$1000,"계획",Sheet1!$C$4:$C$1000," - 재료비") -> 6 | ... P6: =SUMIFS(Sheet1!R$4:R$1000,Sheet1!$A$4:$A$1000,">="&Report_P1!$K$5,Sheet1!$A$4:$A$1000,"<="&Report_P1!$K$6,Sheet1!$B$4:$B$1000,"계획",Sheet1!$C$4:$C$1000," - 재료비") -> 6
A7: 실적재료비 | B7: =SUMIFS(Sheet1!D$4:D$1000,Sheet1!$A$4:$A$1000,">="&Report_P1!$K$5,Sheet1!$A$4:$A$1000,"<="&Report_P1!$K$6,Sheet1!$B$4:$B$1000,"실적",Sheet1!$C$4:$C$1000," - 재료비") -> 3 | C7: =SUMIFS(Sheet1!E$4:E$1000,Sheet1!$A$4:$A$1000,">="&Report_P1!$K$5,Sheet1!$A$4:$A$1000,"<="&Report_P1!$K$6,Sheet1!$B$4:$B$1000,"실적",Sheet1!$C$4:$C$1000," - 재료비") -> 3 | D7: =SUMIFS(Sheet1!F$4:F$1000,Sheet1!$A$4:$A$1000,">="&Report_P1!$K$5,Sheet1!$A$4:$A$1000,"<="&Report_P1!$K$6,Sheet1!$B$4:$B$1000,"실적",Sheet1!$C$4:$C$1000," - 재료비") -> 3 | E7: =SUMIFS(Sheet1!G$4:G$1000,Sheet1!$A$4:$A$1000,">="&Report_P1!$K$5,Sheet1!$A$4:$A$1000,"<="&Report_P1!$K$6,Sheet1!$B$4:$B$1000,"실적",Sheet1!$C$4:$C$1000," - 재료비") -> 6 | F7: =SUMIFS(Sheet1!H$4:H$1000,Sheet1!$A$4:$A$1000,">="&Report_P1!$K$5,Sheet1!$A$4:$A$1000,"<="&Report_P1!$K$6,Sheet1!$B$4:$B$1000,"실적",Sheet1!$C$4:$C$1000," - 재료비") -> 9 | G7: =SUMIFS(Sheet1!I$4:I$1000,Sheet1!$A$4:$A$1000,">="&Report_P1!$K$5,Sheet1!$A$4:$A$1000,"<="&Report_P1!$K$6,Sheet1!$B$4:$B$1000,"실적",Sheet1!$C$4:$C$1000," - 재료비") -> 9 | H7: =SUMIFS(Sheet1!J$4:J$1000,Sheet1!$A$4:$A$1000,">="&Report_P1!$K$5,Sheet1!$A$4:$A$1000,"<="&Report_P1!$K$6,Sheet1!$B$4:$B$1000,"실적",Sheet1!$C$4:$C$1000," - 재료비") -> 9 | I7: =SUMIFS(Sheet1!K$4:K$1000,Sheet1!$A$4:$A$1000,">="&Report_P1!$K$5,Sheet1!$A$4:$A$1000,"<="&Report_P1!$K$6,Sheet1!$B$4:$B$1000,"실적",Sheet1!$C$4:$C$1000," - 재료비") -> 8 | ... P7: =SUMIFS(Sheet1!R$4:R$1000,Sheet1!$A$4:$A$1000,">="&Report_P1!$K$5,Sheet1!$A$4:$A$1000,"<="&Report_P1!$K$6,Sheet1!$B$4:$B$1000,"실적",Sheet1!$C$4:$C$1000," - 재료비") -> 20
A8: 계획노무비 | B8: =SUMIFS(Sheet1!D$4:D$1000,Sheet1!$A$4:$A$1000,">="&Report_P1!$K$5,Sheet1!$A$4:$A$1000,"<="&Report_P1!$K$6,Sheet1!$B$4:$B$1000,"계획",Sheet1!$C$4:$C$1000," - 노무비") -> 2 | C8: =SUMIFS(Sheet1!E$4:E$1000,Sheet1!$A$4:$A$1000,">="&Report_P1!$K$5,Sheet1!$A$4:$A$1000,"<="&Report_P1!$K$6,Sheet1!$B$4:$B$1000,"계획",Sheet1!$C$4:$C$1000," - 노무비") -> 2 | D8: =SUMIFS(Sheet1!F$4:F$1000,Sheet1!$A$4:$A$1000,">="&Report_P1!$K$5,Sheet1!$A$4:$A$1000,"<="&Report_P1!$K$6,Sheet1!$B$4:$B$1000,"계획",Sheet1!$C$4:$C$1000," - 노무비") -> 2 | E8: =SUMIFS(Sheet1!G$4:G$1000,Sheet1!$A$4:$A$1000,">="&Report_P1!$K$5,Sheet1!$A$4:$A$1000,"<="&Report_P1!$K$6,Sheet1!$B$4:$B$1000,"계획",Sheet1!$C$4:$C$1000," - 노무비") -> 0 | F8: =SUMIFS(Sheet1!H$4:H$1000,Sheet1!$A$4:$A$1000,">="&Report_P1!$K$5,Sheet1!$A$4:$A$1000,"<="&Report_P1!$K$6,Sheet1!$B$4:$B$1000,"계획",Sheet1!$C$4:$C$1000," - 노무비") -> 2 | G8: =SUMIFS(Sheet1!I$4:I$1000,Sheet1!$A$4:$A$1000,">="&Report_P1!$K$5,Sheet1!$A$4:$A$1000,"<="&Report_P1!$K$6,Sheet1!$B$4:$B$1000,"계획",Sheet1!$C$4:$C$1000," - 노무비") -> 2 | H8: =SUMIFS(Sheet1!J$4:J$1000,Sheet1!$A$4:$A$1000,">="&Report_P1!$K$5,Sheet1!$A$4:$A$1000,"<="&Report_P1!$K$6,Sheet1!$B$4:$B$1000,"계획",Sheet1!$C$4:$C$1000," - 노무비") -> 2 | I8: =SUMIFS(Sheet1!K$4:K$1000,Sheet1!$A$4:$A$1000,">="&Report_P1!$K$5,Sheet1!$A$4:$A$1000,"<="&Report_P1!$K$6,Sheet1!$B$4:$B$1000,"계획",Sheet1!$C$4:$C$1000," - 노무비") -> 2 | ... P8: =SUMIFS(Sheet1!R$4:R$1000,Sheet1!$A$4:$A$1000,">="&Report_P1!$K$5,Sheet1!$A$4:$A$1000,"<="&Report_P1!$K$6,Sheet1!$B$4:$B$1000,"계획",Sheet1!$C$4:$C$1000," - 노무비") -> 2
A9: 실적노무비 | B9: =SUMIFS(Sheet1!D$4:D$1000,Sheet1!$A$4:$A$1000,">="&Report_P1!$K$5,Sheet1!$A$4:$A$1000,"<="&Report_P1!$K$6,Sheet1!$B$4:$B$1000,"실적",Sheet1!$C$4:$C$1000," - 노무비") -> 2 | C9: =SUMIFS(Sheet1!E$4:E$1000,Sheet1!$A$4:$A$1000,">="&Report_P1!$K$5,Sheet1!$A$4:$A$1000,"<="&Report_P1!$K$6,Sheet1!$B$4:$B$1000,"실적",Sheet1!$C$4:$C$1000," - 노무비") -> 2 | D9: =SUMIFS(Sheet1!F$4:F$1000,Sheet1!$A$4:$A$1000,">="&Report_P1!$K$5,Sheet1!$A$4:$A$1000,"<="&Report_P1!$K$6,Sheet1!$B$4:$B$1000,"실적",Sheet1!$C$4:$C$1000," - 노무비") -> 2 | E9: =SUMIFS(Sheet1!G$4:G$1000,Sheet1!$A$4:$A$1000,">="&Report_P1!$K$5,Sheet1!$A$4:$A$1000,"<="&Report_P1!$K$6,Sheet1!$B$4:$B$1000,"실적",Sheet1!$C$4:$C$1000," - 노무비") -> 0 | F9: =SUMIFS(Sheet1!H$4:H$1000,Sheet1!$A$4:$A$1000,">="&Report_P1!$K$5,Sheet1!$A$4:$A$1000,"<="&Report_P1!$K$6,Sheet1!$B$4:$B$1000,"실적",Sheet1!$C$4:$C$1000," - 노무비") -> 2 | G9: =SUMIFS(Sheet1!I$4:I$1000,Sheet1!$A$4:$A$1000,">="&Report_P1!$K$5,Sheet1!$A$4:$A$1000,"<="&Report_P1!$K$6,Sheet1!$B$4:$B$1000,"실적",Sheet1!$C$4:$C$1000," - 노무비") -> 2 | H9: =SUMIFS(Sheet1!J$4:J$1000,Sheet1!$A$4:$A$1000,">="&Report_P1!$K$5,Sheet1!$A$4:$A$1000,"<="&Report_P1!$K$6,Sheet1!$B$4:$B$1000,"실적",Sheet1!$C$4:$C$1000," - 노무비") -> 2 | I9: =SUMIFS(Sheet1!K$4:K$1000,Sheet1!$A$4:$A$1000,">="&Report_P1!$K$5,Sheet1!$A$4:$A$1000,"<="&Report_P1!$K$6,Sheet1!$B$4:$B$1000,"실적",Sheet1!$C$4:$C$1000," - 노무비") -> 2 | ... P9: =SUMIFS(Sheet1!R$4:R$1000,Sheet1!$A$4:$A$1000,">="&Report_P1!$K$5,Sheet1!$A$4:$A$1000,"<="&Report_P1!$K$6,Sheet1!$B$4:$B$1000,"실적",Sheet1!$C$4:$C$1000," - 노무비") -> 2
A10: 계획경비 | B10: =SUMIFS(Sheet1!D$4:D$1000,Sheet1!$A$4:$A$1000,">="&Report_P1!$K$5,Sheet1!$A$4:$A$1000,"<="&Report_P1!$K$6,Sheet1!$B$4:$B$1000,"계획",Sheet1!$C$4:$C$1000," - 경비") -> 2 | C10: =SUMIFS(Sheet1!E$4:E$1000,Sheet1!$A$4:$A$1000,">="&Report_P1!$K$5,Sheet1!$A$4:$A$1000,"<="&Report_P1!$K$6,Sheet1!$B$4:$B$1000,"계획",Sheet1!$C$4:$C$1000," - 경비") -> 2 | D10: =SUMIFS(Sheet1!F$4:F$1000,Sheet1!$A$4:$A$1000,">="&Report_P1!$K$5,Sheet1!$A$4:$A$1000,"<="&Report_P1!$K$6,Sheet1!$B$4:$B$1000,"계획",Sheet1!$C$4:$C$1000," - 경비") -> 2 | E10: =SUMIFS(Sheet1!G$4:G$1000,Sheet1!$A$4:$A$1000,">="&Report_P1!$K$5,Sheet1!$A$4:$A$1000,"<="&Report_P1!$K$6,Sheet1!$B$4:$B$1000,"계획",Sheet1!$C$4:$C$1000," - 경비") -> 0 | F10: =SUMIFS(Sheet1!H$4:H$1000,Sheet1!$A$4:$A$1000,">="&Report_P1!$K$5,Sheet1!$A$4:$A$1000,"<="&Report_P1!$K$6,Sheet1!$B$4:$B$1000,"계획",Sheet1!$C$4:$C$1000," - 경비") -> 2 | G10: =SUMIFS(Sheet1!I$4:I$1000,Sheet1!$A$4:$A$1000,">="&Report_P1!$K$5,Sheet1!$A$4:$A$1000,"<="&Report_P1!$K$6,Sheet1!$B$4:$B$1000,"계획",Sheet1!$C$4:$C$1000," - 경비") -> 2 | H10: =SUMIFS(Sheet1!J$4:J$1000,Sheet1!$A$4:$A$1000,">="&Report_P1!$K$5,Sheet1!$A$4:$A$1000,"<="&Report_P1!$K$6,Sheet1!$B$4:$B$1000,"계획",Sheet1!$C$4:$C$1000," - 경비") -> 2 | I10: =SUMIFS(Sheet1!K$4:K$1000,Sheet1!$A$4:$A$1000,">="&Report_P1!$K$5,Sheet1!$A$4:$A$1000,"<="&Report_P1!$K$6,Sheet1!$B$4:$B$1000,"계획",Sheet1!$C$4:$C$1000," - 경비") -> 2 | ... P10: =SUMIFS(Sheet1!R$4:R$1000,Sheet1!$A$4:$A$1000,">="&Report_P1!$K$5,Sheet1!$A$4:$A$1000,"<="&Report_P1!$K$6,Sheet1!$B$4:$B$1000,"계획",Sheet1!$C$4:$C$1000," - 경비") -> 2
A11: 실적경비 | B11: =SUMIFS(Sheet1!D$4:D$1000,Sheet1!$A$4:$A$1000,">="&Report_P1!$K$5,Sheet1!$A$4:$A$1000,"<="&Report_P1!$K$6,Sheet1!$B$4:$B$1000,"실적",Sheet1!$C$4:$C$1000," - 경비") -> 2 | C11: =SUMIFS(Sheet1!E$4:E$1000,Sheet1!$A$4:$A$1000,">="&Report_P1!$K$5,Sheet1!$A$4:$A$1000,"<="&Report_P1!$K$6,Sheet1!$B$4:$B$1000,"실적",Sheet1!$C$4:$C$1000," - 경비") -> 2 | D11: =SUMIFS(Sheet1!F$4:F$1000,Sheet1!$A$4:$A$1000,">="&Report_P1!$K$5,Sheet1!$A$4:$A$1000,"<="&Report_P1!$K$6,Sheet1!$B$4:$B$1000,"실적",Sheet1!$C$4:$C$1000," - 경비") -> 2 | E11: =SUMIFS(Sheet1!G$4:G$1000,Sheet1!$A$4:$A$1000,">="&Report_P1!$K$5,Sheet1!$A$4:$A$1000,"<="&Report_P1!$K$6,Sheet1!$B$4:$B$1000,"실적",Sheet1!$C$4:$C$1000," - 경비") -> 0 | F11: =SUMIFS(Sheet1!H$4:H$1000,Sheet1!$A$4:$A$1000,">="&Report_P1!$K$5,Sheet1!$A$4:$A$1000,"<="&Report_P1!$K$6,Sheet1!$B$4:$B$1000,"실적",Sheet1!$C$4:$C$1000," - 경비") -> 2 | G11: =SUMIFS(Sheet1!I$4:I$1000,Sheet1!$A$4:$A$1000,">="&Report_P1!$K$5,Sheet1!$A$4:$A$1000,"<="&Report_P1!$K$6,Sheet1!$B$4:$B$1000,"실적",Sheet1!$C$4:$C$1000," - 경비") -> 2 | H11: =SUMIFS(Sheet1!J$4:J$1000,Sheet1!$A$4:$A$1000,">="&Report_P1!$K$5,Sheet1!$A$4:$A$1000,"<="&Report_P1!$K$6,Sheet1!$B$4:$B$1000,"실적",Sheet1!$C$4:$C$1000," - 경비") -> 2 | I11: =SUMIFS(Sheet1!K$4:K$1000,Sheet1!$A$4:$A$1000,">="&Report_P1!$K$5,Sheet1!$A$4:$A$1000,"<="&Report_P1!$K$6,Sheet1!$B$4:$B$1000,"실적",Sheet1!$C$4:$C$1000," - 경비") -> 2 | ... P11: =SUMIFS(Sheet1!R$4:R$1000,Sheet1!$A$4:$A$1000,">="&Report_P1!$K$5,Sheet1!$A$4:$A$1000,"<="&Report_P1!$K$6,Sheet1!$B$4:$B$1000,"실적",Sheet1!$C$4:$C$1000," - 경비") -> 2
A12: 계획판관비 | B12: =SUMIFS(Sheet1!D$4:D$1000,Sheet1!$A$4:$A$1000,">="&Report_P1!$K$5,Sheet1!$A$4:$A$1000,"<="&Report_P1!$K$6,Sheet1!$B$4:$B$1000,"계획",Sheet1!$C$4:$C$1000,"판관비") -> 2 | C12: =SUMIFS(Sheet1!E$4:E$1000,Sheet1!$A$4:$A$1000,">="&Report_P1!$K$5,Sheet1!$A$4:$A$1000,"<="&Report_P1!$K$6,Sheet1!$B$4:$B$1000,"계획",Sheet1!$C$4:$C$1000,"판관비") -> 2 | D12: =SUMIFS(Sheet1!F$4:F$1000,Sheet1!$A$4:$A$1000,">="&Report_P1!$K$5,Sheet1!$A$4:$A$1000,"<="&Report_P1!$K$6,Sheet1!$B$4:$B$1000,"계획",Sheet1!$C$4:$C$1000,"판관비") -> 2 | E12: =SUMIFS(Sheet1!G$4:G$1000,Sheet1!$A$4:$A$1000,">="&Report_P1!$K$5,Sheet1!$A$4:$A$1000,"<="&Report_P1!$K$6,Sheet1!$B$4:$B$1000,"계획",Sheet1!$C$4:$C$1000,"판관비") -> 2 | F12: =SUMIFS(Sheet1!H$4:H$1000,Sheet1!$A$4:$A$1000,">="&Report_P1!$K$5,Sheet1!$A$4:$A$1000,"<="&Report_P1!$K$6,Sheet1!$B$4:$B$1000,"계획",Sheet1!$C$4:$C$1000,"판관비") -> 2 | G12: =SUMIFS(Sheet1!I$4:I$1000,Sheet1!$A$4:$A$1000,">="&Report_P1!$K$5,Sheet1!$A$4:$A$1000,"<="&Report_P1!$K$6,Sheet1!$B$4:$B$1000,"계획",Sheet1!$C$4:$C$1000,"판관비") -> 2 | H12: =SUMIFS(Sheet1!J$4:J$1000,Sheet1!$A$4:$A$1000,">="&Report_P1!$K$5,Sheet1!$A$4:$A$1000,"<="&Report_P1!$K$6,Sheet1!$B$4:$B$1000,"계획",Sheet1!$C$4:$C$1000,"판관비") -> 2 | I12: =SUMIFS(Sheet1!K$4:K$1000,Sheet1!$A$4:$A$1000,">="&Report_P1!$K$5,Sheet1!$A$4:$A$1000,"<="&Report_P1!$K$6,Sheet1!$B$4:$B$1000,"계획",Sheet1!$C$4:$C$1000,"판관비") -> 2 | ... P12: =SUMIFS(Sheet1!R$4:R$1000,Sheet1!$A$4:$A$1000,">="&Report_P1!$K$5,Sheet1!$A$4:$A$1000,"<="&Report_P1!$K$6,Sheet1!$B$4:$B$1000,"계획",Sheet1!$C$4:$C$1000,"판관비") -> 2
A13: 실적판관비 | B13: =SUMIFS(Sheet1!D$4:D$1000,Sheet1!$A$4:$A$1000,">="&Report_P1!$K$5,Sheet1!$A$4:$A$1000,"<="&Report_P1!$K$6,Sheet1!$B$4:$B$1000,"실적",Sheet1!$C$4:$C$1000,"판관비") -> 6 | C13: =SUMIFS(Sheet1!E$4:E$1000,Sheet1!$A$4:$A$1000,">="&Report_P1!$K$5,Sheet1!$A$4:$A$1000,"<="&Report_P1!$K$6,Sheet1!$B$4:$B$1000,"실적",Sheet1!$C$4:$C$1000,"판관비") -> 6 | D13: =SUMIFS(Sheet1!F$4:F$1000,Sheet1!$A$4:$A$1000,">="&Report_P1!$K$5,Sheet1!$A$4:$A$1000,"<="&Report_P1!$K$6,Sheet1!$B$4:$B$1000,"실적",Sheet1!$C$4:$C$1000,"판관비") -> 6 | E13: =SUMIFS(Sheet1!G$4:G$1000,Sheet1!$A$4:$A$1000,">="&Report_P1!$K$5,Sheet1!$A$4:$A$1000,"<="&Report_P1!$K$6,Sheet1!$B$4:$B$1000,"실적",Sheet1!$C$4:$C$1000,"판관비") -> 4 | F13: =SUMIFS(Sheet1!H$4:H$1000,Sheet1!$A$4:$A$1000,">="&Report_P1!$K$5,Sheet1!$A$4:$A$1000,"<="&Report_P1!$K$6,Sheet1!$B$4:$B$1000,"실적",Sheet1!$C$4:$C$1000,"판관비") -> 1 | G13: =SUMIFS(Sheet1!I$4:I$1000,Sheet1!$A$4:$A$1000,">="&Report_P1!$K$5,Sheet1!$A$4:$A$1000,"<="&Report_P1!$K$6,Sheet1!$B$4:$B$1000,"실적",Sheet1!$C$4:$C$1000,"판관비") -> 1 | H13: =SUMIFS(Sheet1!J$4:J$1000,Sheet1!$A$4:$A$1000,">="&Report_P1!$K$5,Sheet1!$A$4:$A$1000,"<="&Report_P1!$K$6,Sheet1!$B$4:$B$1000,"실적",Sheet1!$C$4:$C$1000,"판관비") -> 1 | I13: =SUMIFS(Sheet1!K$4:K$1000,Sheet1!$A$4:$A$1000,">="&Report_P1!$K$5,Sheet1!$A$4:$A$1000,"<="&Report_P1!$K$6,Sheet1!$B$4:$B$1000,"실적",Sheet1!$C$4:$C$1000,"판관비") -> 2 | ... P13: =SUMIFS(Sheet1!R$4:R$1000,Sheet1!$A$4:$A$1000,">="&Report_P1!$K$5,Sheet1!$A$4:$A$1000,"<="&Report_P1!$K$6,Sheet1!$B$4:$B$1000,"실적",Sheet1!$C$4:$C$1000,"판관비") -> 5
A14: 계획영업외 | B14: =SUMIFS(Sheet1!D$4:D$1000,Sheet1!$A$4:$A$1000,">="&Report_P1!$K$5,Sheet1!$A$4:$A$1000,"<="&Report_P1!$K$6,Sheet1!$B$4:$B$1000,"계획",Sheet1!$C$4:$C$1000,"영업외") -> -2 | C14: =SUMIFS(Sheet1!E$4:E$1000,Sheet1!$A$4:$A$1000,">="&Report_P1!$K$5,Sheet1!$A$4:$A$1000,"<="&Report_P1!$K$6,Sheet1!$B$4:$B$1000,"계획",Sheet1!$C$4:$C$1000,"영업외") -> -2 | D14: =SUMIFS(Sheet1!F$4:F$1000,Sheet1!$A$4:$A$1000,">="&Report_P1!$K$5,Sheet1!$A$4:$A$1000,"<="&Report_P1!$K$6,Sheet1!$B$4:$B$1000,"계획",Sheet1!$C$4:$C$1000,"영업외") -> -2 | E14: =SUMIFS(Sheet1!G$4:G$1000,Sheet1!$A$4:$A$1000,">="&Report_P1!$K$5,Sheet1!$A$4:$A$1000,"<="&Report_P1!$K$6,Sheet1!$B$4:$B$1000,"계획",Sheet1!$C$4:$C$1000,"영업외") -> -2 | F14: =SUMIFS(Sheet1!H$4:H$1000,Sheet1!$A$4:$A$1000,">="&Report_P1!$K$5,Sheet1!$A$4:$A$1000,"<="&Report_P1!$K$6,Sheet1!$B$4:$B$1000,"계획",Sheet1!$C$4:$C$1000,"영업외") -> -2 | G14: =SUMIFS(Sheet1!I$4:I$1000,Sheet1!$A$4:$A$1000,">="&Report_P1!$K$5,Sheet1!$A$4:$A$1000,"<="&Report_P1!$K$6,Sheet1!$B$4:$B$1000,"계획",Sheet1!$C$4:$C$1000,"영업외") -> -2 | H14: =SUMIFS(Sheet1!J$4:J$1000,Sheet1!$A$4:$A$1000,">="&Report_P1!$K$5,Sheet1!$A$4:$A$1000,"<="&Report_P1!$K$6,Sheet1!$B$4:$B$1000,"계획",Sheet1!$C$4:$C$1000,"영업외") -> -2 | I14: =SUMIFS(Sheet1!K$4:K$1000,Sheet1!$A$4:$A$1000,">="&Report_P1!$K$5,Sheet1!$A$4:$A$1000,"<="&Report_P1!$K$6,Sheet1!$B$4:$B$1000,"계획",Sheet1!$C$4:$C$1000,"영업외") -> -2 | ... P14: =SUMIFS(Sheet1!R$4:R$1000,Sheet1!$A$4:$A$1000,">="&Report_P1!$K$5,Sheet1!$A$4:$A$1000,"<="&Report_P1!$K$6,Sheet1!$B$4:$B$1000,"계획",Sheet1!$C$4:$C$1000,"영업외") -> -2
A15: 실적영업외 | B15: =SUMIFS(Sheet1!D$4:D$1000,Sheet1!$A$4:$A$1000,">="&Report_P1!$K$5,Sheet1!$A$4:$A$1000,"<="&Report_P1!$K$6,Sheet1!$B$4:$B$1000,"실적",Sheet1!$C$4:$C$1000,"영업외") -> 1 | C15: =SUMIFS(Sheet1!E$4:E$1000,Sheet1!$A$4:$A$1000,">="&Report_P1!$K$5,Sheet1!$A$4:$A$1000,"<="&Report_P1!$K$6,Sheet1!$B$4:$B$1000,"실적",Sheet1!$C$4:$C$1000,"영업외") -> 1 | D15: =SUMIFS(Sheet1!F$4:F$1000,Sheet1!$A$4:$A$1000,">="&Report_P1!$K$5,Sheet1!$A$4:$A$1000,"<="&Report_P1!$K$6,Sheet1!$B$4:$B$1000,"실적",Sheet1!$C$4:$C$1000,"영업외") -> 1 | E15: =SUMIFS(Sheet1!G$4:G$1000,Sheet1!$A$4:$A$1000,">="&Report_P1!$K$5,Sheet1!$A$4:$A$1000,"<="&Report_P1!$K$6,Sheet1!$B$4:$B$1000,"실적",Sheet1!$C$4:$C$1000,"영업외") -> 2 | F15: =SUMIFS(Sheet1!H$4:H$1000,Sheet1!$A$4:$A$1000,">="&Report_P1!$K$5,Sheet1!$A$4:$A$1000,"<="&Report_P1!$K$6,Sheet1!$B$4:$B$1000,"실적",Sheet1!$C$4:$C$1000,"영업외") -> -3 | G15: =SUMIFS(Sheet1!I$4:I$1000,Sheet1!$A$4:$A$1000,">="&Report_P1!$K$5,Sheet1!$A$4:$A$1000,"<="&Report_P1!$K$6,Sheet1!$B$4:$B$1000,"실적",Sheet1!$C$4:$C$1000,"영업외") -> -3 | H15: =SUMIFS(Sheet1!J$4:J$1000,Sheet1!$A$4:$A$1000,">="&Report_P1!$K$5,Sheet1!$A$4:$A$1000,"<="&Report_P1!$K$6,Sheet1!$B$4:$B$1000,"실적",Sheet1!$C$4:$C$1000,"영업외") -> -3 | I15: =SUMIFS(Sheet1!K$4:K$1000,Sheet1!$A$4:$A$1000,">="&Report_P1!$K$5,Sheet1!$A$4:$A$1000,"<="&Report_P1!$K$6,Sheet1!$B$4:$B$1000,"실적",Sheet1!$C$4:$C$1000,"영업외") -> -4 | ... P15: =SUMIFS(Sheet1!R$4:R$1000,Sheet1!$A$4:$A$1000,">="&Report_P1!$K$5,Sheet1!$A$4:$A$1000,"<="&Report_P1!$K$6,Sheet1!$B$4:$B$1000,"실적",Sheet1!$C$4:$C$1000,"영업외") -> -5
A16: 계획롤마진 | B16: =IFERROR((B4/B2)-(B6/B2),0) -> 0.625 | C16: =IFERROR((C4/C2)-(C6/C2),0) -> 0.625 | D16: =IFERROR((D4/D2)-(D6/D2),0) -> 0.625 | E16: =IFERROR((E4/E2)-(E6/E2),0) -> 0.25 | F16: =IFERROR((F4/F2)-(F6/F2),0) -> 0.625 | G16: =IFERROR((G4/G2)-(G6/G2),0) -> 0.625 | H16: =IFERROR((H4/H2)-(H6/H2),0) -> 0.625 | I16: =IFERROR((I4/I2)-(I6/I2),0) -> 0.625 | ... P16: =IFERROR((P4/P2)-(P6/P2),0) -> 0.625
A17: 실적롤마진 | B17: =IFERROR((B5/B3)-(B7/B3),0) -> 0.64705882 | C17: =IFERROR((C5/C3)-(C7/C3),0) -> 0.64705882 | D17: =IFERROR((D5/D3)-(D7/D3),0) -> 0.64705882 | E17: =IFERROR((E5/E3)-(E7/E3),0) -> 0.25 | F17: =IFERROR((F5/F3)-(F7/F3),0) -> 0.75 | G17: =IFERROR((G5/G3)-(G7/G3),0) -> 0.75 | H17: =IFERROR((H5/H3)-(H7/H3),0) -> 0.75 | I17: =IFERROR((I5/I3)-(I7/I3),0) -> 0.44444444 | ... P17: =IFERROR((P5/P3)-(P7/P3),0) -> 0.66666667
A18: 계획제경비 | B18: =B8+B10+B12 -> 6 | C18: =C8+C10+C12 -> 6 | D18: =D8+D10+D12 -> 6 | E18: =E8+E10+E12 -> 2 | F18: =F8+F10+F12 -> 6 | G18: =G8+G10+G12 -> 6 | H18: =H8+H10+H12 -> 6 | I18: =I8+I10+I12 -> 6 | ... P18: =P8+P10+P12 -> 6
A19: 실적제경비 | B19: =B9+B11+B13 -> 10 | C19: =C9+C11+C13 -> 10 | D19: =D9+D11+D13 -> 10 | E19: =E9+E11+E13 -> 4 | F19: =F9+F11+F13 -> 5 | G19: =G9+G11+G13 -> 5 | H19: =H9+H11+H13 -> 5 | I19: =I9+I11+I13 -> 6 | ... P19: =P9+P11+P13 -> 9
